Workbook

Sheet README
A1: База мест Voyz — одна карточка на лист
A2: Выгружено 2026-10-21 · карточек: 112
A4: Как пользоваться
A5: «Оглавление» — список всех карточек со ссылками (клик по id открывает лист). Сводка справа.
A6: Лист карточки называется её id (kg-skazka). Разделы идут в порядке карточки в приложении: Основное → Плашки → Тексты → Медиа → Дорога → Сезон → Важно → Ночлег и еда → На месте → Сервисы → Бюджет → Отзывы → Рядом → Проверка → Перевод EN.
A7: Поля: подпись в колонке B, значение — в колонке C. Жёлтая подпись — обязательное поле. Выпадающие списки — у страны, публикации, статуса, категории, региона, плашек.
A8: Списки (фото, подъезды, ночлег, тропы…): зелёная строка с названием, под ней подписи колонок и записи. Новая запись — в пустую строку под таблицей; если нужно больше, вставьте строку (Ctrl+«+») внутри таблицы.
A9: Колонку A (серые служебные метки) не трогайте — по ним программа читает файл.
A11: Как добавить новое место
A12: 1. Правой кнопкой по листу «_шаблон» → «Переместить или скопировать» → «Создать копию».
A13: 2. Переименуйте копию в id нового места: kg-… или alt-…, латиница и дефисы (например kg-ala-kul). В поле id впишите то же самое.
A14: 3. Заполните жёлтые поля, добавьте фото (файлы — в папку assets/img проекта), подъезды, ночлег. Публикация = черновик, пока не готово.
... A27: Схема и проверки — tools/places_xlsx.py, чтение/запись этого формата — tools/places_cards.py, описание — docs/09_DATA_EXCEL.md.

Sheet Оглавление
A1: id | B1: name | C1: country | D1: publish | E1: status | F1: cat | G1: reg | H1: photos | I1: routes | J1: stays
A2: Карточка (ссылка) | B2: Название | C2: Страна | D2: Публикация | E2: Статус | F2: Категория | G2: Регион | H2: Фото | I2: Подъездов | J2: Ночлег | L2: Сводка
A3: kg-skazka | B3: ='kg-skazka'!C7 | C3: ='kg-skazka'!C4 | D3: ='kg-skazka'!C5 | E3: ='kg-skazka'!C6 | F3: ='kg-skazka'!C9 | G3: ='kg-skazka'!C10 | H3: 2 | I3: 3 | J3: 8 | L3: Карточек | M3: =COUNTA(A3:A114)
A4: kg-altyn-arashan | B4: ='kg-altyn-arashan'!C7 | C4: ='kg-altyn-arashan'!C4 | D4: ='kg-altyn-arashan'!C5 | E4: ='kg-altyn-arashan'!C6 | F4: ='kg-altyn-arashan'!C9 | G4: ='kg-altyn-arashan'!C10 | H4: 2 | I4: 2 | J4: 7 | L4: Кыргызстан | M4: =COUNTIF(C3:C114,"kg")
A5: kg-son-kul | B5: ='kg-son-kul'!C7 | C5: ='kg-son-kul'!C4 | D5: ='kg-son-kul'!C5 | E5: ='kg-son-kul'!C6 | F5: ='kg-son-kul'!C9 | G5: ='kg-son-kul'!C10 | H5: 2 | I5: 5 | J5: 8 | L5: Алтай | M5: =COUNTIF(C3:C114,"alt")
A6: kg-0002 | B6: ='kg-0002'!C7 | C6: ='kg-0002'!C4 | D6: ='kg-0002'!C5 | E6: ='kg-0002'!C6 | F6: ='kg-0002'!C9 | G6: ='kg-0002'!C10 | H6: 0 | I6: 2 | J6: 4 | L6: Опубликовано | M6: =COUNTIF(D3:D114,"опубликовано")
A7: kg-0003 | B7: ='kg-0003'!C7 | C7: ='kg-0003'!C4 | D7: ='kg-0003'!C5 | E7: ='kg-0003'!C6 | F7: ='kg-0003'!C9 | G7: ='kg-0003'!C10 | H7: 2 | I7: 1 | J7: 6 | L7: Черновиков | M7: =COUNTIF(D3:D114,"черновик")
A8: kg-0004 | B8: ='kg-0004'!C7 | C8: ='kg-0004'!C4 | D8: ='kg-0004'!C5 | E8: ='kg-0004'!C6 | F8: ='kg-0004'!C9 | G8: ='kg-0004'!C10 | H8: 2 | I8: 3 | J8: 5 | L8: Без фото | M8: =COUNTIF(H3:H114,0)
A9: kg-0007 | B9: ='kg-0007'!C7 | C9: ='kg-0007'!C4 | D9: ='kg-0007'!C5 | E9: ='kg-0007'!C6 | F9: ='kg-0007'!C9 | G9: ='kg-0007'!C10 | H9: 2 | I9: 2 | J9: 7 | L9: Открытых тикетов | M9: =COUNTIF('Тикеты'!F:F,"открыт")
A10: kg-0009 | B10: ='kg-0009'!C7 | C10: ='kg-0009'!C4 | D10: ='kg-0009'!C5 | E10: ='kg-0009'!C6 | F10: ='kg-0009'!C9 | G10: ='kg-0009'!C10 | H10: 2 | I10: 4 | J10: 8 | L10: В работе | M10: =COUNTIF('Тикеты'!F:F,"в работе")
A11: kg-0010 | B11: ='kg-0010'!C7 | C11: ='kg-0010'!C4 | D11: ='kg-0010'!C5 | E11: ='kg-0010'!C6 | F11: ='kg-0010'!C9 | G11: ='kg-0010'!C10 | H11: 2 | I11: 2 | J11: 5
A12: kg-0011 | B12: ='kg-0011'!C7 | C12: ='kg-0011'!C4 | D12: ='kg-0011'!C5 | E12: ='kg-0011'!C6 | F12: ='kg-0011'!C9 | G12: ='kg-0011'!C10 | H12: 2 | I12: 3 | J12: 6 | L12: Фото/подъезды/ночлег — на момент выгрузки
A13: kg-0012 | B13: ='kg-0012'!C7 | C13: ='kg-0012'!C4 | D13: ='kg-0012'!C5 | E13: ='kg-0012'!C6 | F13: ='kg-0012'!C9 | G13: ='kg-0012'!C10 | H13: 1 | I13: 1 | J13: 8
A14: kg-0013 | B14: ='kg-0013'!C7 | C14: ='kg-0013'!C4 | D14: ='kg-0013'!C5 | E14: ='kg-0013'!C6 | F14: ='kg-0013'!C9 | G14: ='kg-0013'!C10 | H14: 0 | I14: 2 | J14: 6
A15: kg-0014 | B15: ='kg-0014'!C7 | C15: ='kg-0014'!C4 | D15: ='kg-0014'!C5 | E15: ='kg-0014'!C6 | F15: ='kg-0014'!C9 | G15: ='kg-0014'!C10 | H15: 2 | I15: 1 | J15: 6
A16: kg-0016 | B16: ='kg-0016'!C7 | C16: ='kg-0016'!C4 | D16: ='kg-0016'!C5 | E16: ='kg-0016'!C6 | F16: ='kg-0016'!C9 | G16: ='kg-0016'!C10 | H16: 1 | I16: 1 | J16: 6
A17: kg-0017 | B17: ='kg-0017'!C7 | C17: ='kg-0017'!C4 | D17: ='kg-0017'!C5 | E17: ='kg-0017'!C6 | F17: ='kg-0017'!C9 | G17: ='kg-0017'!C10 | H17: 2 | I17: 2 | J17: 4
A18: kg-0018 | B18: ='kg-0018'!C7 | C18: ='kg-0018'!C4 | D18: ='kg-0018'!C5 | E18: ='kg-0018'!C6 | F18: ='kg-0018'!C9 | G18: ='kg-0018'!C10 | H18: 0 | I18: 2 | J18: 3
A19: kg-0019 | B19: ='kg-0019'!C7 | C19: ='kg-0019'!C4 | D19: ='kg-0019'!C5 | E19: ='kg-0019'!C6 | F19: ='kg-0019'!C9 | G19: ='kg-0019'!C10 | H19: 0 | I19: 2 | J19: 3
A20: kg-0020 | B20: ='kg-0020'!C7 | C20: ='kg-0020'!C4 | D20: ='kg-0020'!C5 | E20: ='kg-0020'!C6 | F20: ='kg-0020'!C9 | G20: ='kg-0020'!C10 | H20: 0 | I20: 1 | J20: 6
A21: kg-0021 | B21: ='kg-0021'!C7 | C21: ='kg-0021'!C4 | D21: ='kg-0021'!C5 | E21: ='kg-0021'!C6 | F21: ='kg-0021'!C9 | G21: ='kg-0021'!C10 | H21: 1 | I21: 2 | J21: 6
A22: kg-0022 | B22: ='kg-0022'!C7 | C22: ='kg-0022'!C4 | D22: ='kg-0022'!C5 | E22: ='kg-0022'!C6 | F22: ='kg-0022'!C9 | G22: ='kg-0022'!C10 | H22: 0 | I22: 1 | J22: 5
A23: kg-0023 | B23: ='kg-0023'!C7 | C23: ='kg-0023'!C4 | D23: ='kg-0023'!C5 | E23: ='kg-0023'!C6 | F23: ='kg-0023'!C9 | G23: ='kg-0023'!C10 | H23: 2 | I23: 1 | J23: 4
A24: kg-0027 | B24: ='kg-0027'!C7 | C24: ='kg-0027'!C4 | D24: ='kg-0027'!C5 | E24: ='kg-0027'!C6 | F24: ='kg-0027'!C9 | G24: ='kg-0027'!C10 | H24: 2 | I24: 2 | J24: 6
A25: kg-0028 | B25: ='kg-0028'!C7 | C25: ='kg-0028'!C4 | D25: ='kg-0028'!C5 | E25: ='kg-0028'!C6 | F25: ='kg-0028'!C9 | G25: ='kg-0028'!C10 | H25: 0 | I25: 1 | J25: 7
A26: kg-0029 | B26: ='kg-0029'!C7 | C26: ='kg-0029'!C4 | D26: ='kg-0029'!C5 | E26: ='kg-0029'!C6 | F26: ='kg-0029'!C9 | G26: ='kg-0029'!C10 | H26: 2 | I26: 2 | J26: 2
A27: kg-0030 | B27: ='kg-0030'!C7 | C27: ='kg-0030'!C4 | D27: ='kg-0030'!C5 | E27: ='kg-0030'!C6 | F27: ='kg-0030'!C9 | G27: ='kg-0030'!C10 | H27: 1 | I27: 1 | J27: 5
A28: kg-0031 | B28: ='kg-0031'!C7 | C28: ='kg-0031'!C4 | D28: ='kg-0031'!C5 | E28: ='kg-0031'!C6 | F28: ='kg-0031'!C9 | G28: ='kg-0031'!C10 | H28: 0 | I28: 3 | J28: 5
A29: kg-0032 | B29: ='kg-0032'!C7 | C29: ='kg-0032'!C4 | D29: ='kg-0032'!C5 | E29: ='kg-0032'!C6 | F29: ='kg-0032'!C9 | G29: ='kg-0032'!C10 | H29: 2 | I29: 2 | J29: 6
A30: kg-0033 | B30: ='kg-0033'!C7 | C30: ='kg-0033'!C4 | D30: ='kg-0033'!C5 | E30: ='kg-0033'!C6 | F30: ='kg-0033'!C9 | G30: ='kg-0033'!C10 | H30: 0 | I30: 2 | J30: 5
A31: kg-0034 | B31: ='kg-0034'!C7 | C31: ='kg-0034'!C4 | D31: ='kg-0034'!C5 | E31: ='kg-0034'!C6 | F31: ='kg-0034'!C9 | G31: ='kg-0034'!C10 | H31: 2 | I31: 1 | J31: 3
A32: kg-0036 | B32: ='kg-0036'!C7 | C32: ='kg-0036'!C4 | D32: ='kg-0036'!C5 | E32: ='kg-0036'!C6 | F32: ='kg-0036'!C9 | G32: ='kg-0036'!C10 | H32: 0 | I32: 2 | J32: 6
A33: kg-0038 | B33: ='kg-0038'!C7 | C33: ='kg-0038'!C4 | D33: ='kg-0038'!C5 | E33: ='kg-0038'!C6 | F33: ='kg-0038'!C9 | G33: ='kg-0038'!C10 | H33: 1 | I33: 3 | J33: 4
A34: kg-0039 | B34: ='kg-0039'!C7 | C34: ='kg-0039'!C4 | D34: ='kg-0039'!C5 | E34: ='kg-0039'!C6 | F34: ='kg-0039'!C9 | G34: ='kg-0039'!C10 | H34: 2 | I34: 4 | J34: 9
A35: kg-0040 | B35: ='kg-0040'!C7 | C35: ='kg-0040'!C4 | D35: ='kg-0040'!C5 | E35: ='kg-0040'!C6 | F35: ='kg-0040'!C9 | G35: ='kg-0040'!C10 | H35: 0 | I35: 2 | J35: 4
A36: kg-0041 | B36: ='kg-0041'!C7 | C36: ='kg-0041'!C4 | D36: ='kg-0041'!C5 | E36: ='kg-0041'!C6 | F36: ='kg-0041'!C9 | G36: ='kg-0041'!C10 | H36: 2 | I36: 2 | J36: 3
A37: kg-0042 | B37: ='kg-0042'!C7 | C37: ='kg-0042'!C4 | D37: ='kg-0042'!C5 | E37: ='kg-0042'!C6 | F37: ='kg-0042'!C9 | G37: ='kg-0042'!C10 | H37: 2 | I37: 2 | J37: 4
A38: kg-0043 | B38: ='kg-0043'!C7 | C38: ='kg-0043'!C4 | D38: ='kg-0043'!C5 | E38: ='kg-0043'!C6 | F38: ='kg-0043'!C9 | G38: ='kg-0043'!C10 | H38: 2 | I38: 2 | J38: 5
A39: kg-0044 | B39: ='kg-0044'!C7 | C39: ='kg-0044'!C4 | D39: ='kg-0044'!C5 | E39: ='kg-0044'!C6 | F39: ='kg-0044'!C9 | G39: ='kg-0044'!C10 | H39: 2 | I39: 2 | J39: 5
A40: kg-0045 | B40: ='kg-0045'!C7 | C40: ='kg-0045'!C4 | D40: ='kg-0045'!C5 | E40: ='kg-0045'!C6 | F40: ='kg-0045'!C9 | G40: ='kg-0045'!C10 | H40: 2 | I40: 2 | J40: 5
...

Sheet Теги
A1: tag_id | B1: name_ru | C1: name_en | D1: group | E1: description
A2: ID тега (латиница, дефис) | B2: Название RU | C2: Название EN | D2: Группа | E2: Описание
A3: lakes | B3: Озёра | C3: Lakes | D3: категория | E3: Категория «Озёра» (по полю cat)
A4: waterfalls | B4: Водопады | C4: Waterfalls | D4: категория | E4: Категория «Водопады» (по полю cat)
A5: canyons | B5: Каньоны | C5: Canyons | D5: категория | E5: Категория «Каньоны» (по полю cat)
A6: gorges | B6: Ущелья | C6: Gorges | D6: категория | E6: Категория «Ущелья» (по полю cat)
A7: passes | B7: Перевалы и дороги | C7: Passes & roads | D7: категория | E7: Категория «Перевалы и дороги» (по полю cat)
A8: valleys | B8: Долины и панорамы | C8: Valleys & views | D8: категория | E8: Категория «Долины и панорамы» (по полю cat)
A9: mountains | B9: Горы и ледники | C9: Mountains & glaciers | D9: категория | E9: Категория «Горы и ледники» (по полю cat)
A10: parks | B10: Парки и заповедники | C10: Parks & reserves | D10: категория | E10: Категория «Парки и заповедники» (по полю cat)
A11: springs | B11: Источники и курорты | C11: Springs & resorts | D11: категория | E11: Категория «Источники и курорты» (по полю cat)
A12: culture | B12: История и культура | C12: History & culture | D12: категория | E12: Категория «История и культура» (по полю cat)
... A28: hard | B28: Сложное | C28: Hard | D28: сложность | E28: Сложность: высокая

Sheet Тикеты
A1: ticket_id | B1: type | C1: place_id | D1: title | E1: details | F1: status | G1: priority | H1: assignee | I1: created | J1: due | K1: source | L1: done_at
A2: № тикета | B2: Тип | C2: Карточка (id) | D2: Задача | E2: Подробности | F2: Статус | G2: Приоритет | H2: Исполнитель | I2: Создан | J2: Срок | K2: Откуда задача | L2: Закрыт
A3: T-0001 | B3: Фото | C3: kg-0002 | D3: Ущелье Кара-Булак: нет свободных фото | E3: Найти фото с лицензией CC/своё, добавить в assets/img и лист photos | F3: открыт | G3: средний | I3: 2026-10-21 | K3: photos пусто
A4: T-0002 | B4: Фото | C4: kg-0013 | D4: Культурный центр Рух-Ордо: нет свободных фото | E4: Найти фото с лицензией CC/своё, добавить в assets/img и лист photos | F4: открыт | G4: средний | I4: 2026-10-21 | K4: photos пусто
A5: T-0003 | B5: Фото | C5: kg-0018 | D5: Ущелье Чон-Ак-Суу: нет свободных фото | E5: Найти фото с лицензией CC/своё, добавить в assets/img и лист photos | F5: открыт | G5: средний | I5: 2026-10-21 | K5: photos пусто
A6: T-0004 | B6: Фото | C6: kg-0019 | D6: Перевал Кара-Кече: нет свободных фото | E6: Найти фото с лицензией CC/своё, добавить в assets/img и лист photos | F6: открыт | G6: средний | I6: 2026-10-21 | K6: photos пусто
A7: T-0005 | B7: Фото | C7: kg-0020 | D7: Каньоны Ак-Сай: нет свободных фото | E7: Найти фото с лицензией CC/своё, добавить в assets/img и лист photos | F7: открыт | G7: средний | I7: 2026-10-21 | K7: photos пусто
A8: T-0006 | B8: Фото | C8: kg-0022 | D8: Ущелье Шамси: нет свободных фото | E8: Найти фото с лицензией CC/своё, добавить в assets/img и лист photos | F8: открыт | G8: средний | I8: 2026-10-21 | K8: photos пусто
A9: T-0007 | B9: Фото | C9: kg-0028 | D9: Водопад Кегеты: нет свободных фото | E9: Найти фото с лицензией CC/своё, добавить в assets/img и лист photos | F9: открыт | G9: средний | I9: 2026-10-21 | K9: photos пусто
A10: T-0008 | B10: Фото | C10: kg-0031 | D10: Горячие источники Джууку: нет свободных фото | E10: Найти фото с лицензией CC/своё, добавить в assets/img и лист photos | F10: открыт | G10: средний | I10: 2026-10-21 | K10: photos пусто
A11: T-0009 | B11: Фото | C11: kg-0033 | D11: Панорама Шатылы: нет свободных фото | E11: Найти фото с лицензией CC/своё, добавить в assets/img и лист photos | F11: открыт | G11: средний | I11: 2026-10-21 | K11: photos пусто
A12: T-0010 | B12: Фото | C12: kg-0036 | D12: Семеновское ущелье: нет свободных фото | E12: Найти фото с лицензией CC/своё, добавить в assets/img и лист photos | F12: открыт | G12: средний | I12: 2026-10-21 | K12: photos пусто
A13: T-0011 | B13: Уточнить координаты | C13: kg-0038 | D13: Ущелье Каравшин: координаты уточняются | E13: Сверить точку с картой/треком, обновить lat/lon и подъезды | F13: открыт | G13: высокий | I13: 2026-10-21 | K13: status в данных
A14: T-0012 | B14: Фото | C14: kg-0040 | D14: Перевал Кызарт: нет свободных фото | E14: Найти фото с лицензией CC/своё, добавить в assets/img и лист photos | F14: открыт | G14: средний | I14: 2026-10-21 | K14: photos пусто
... A149: T-0147 | B149: Перевод EN | C149: alt-31 | D149: Гора Белуха и Аккемское озеро: вычитать EN-перевод | E149: Лист translations_en; после проверки поставить en_reviewed = да на листе places | F149: открыт | G149: низкий | I149: 2026-10-21 | K149: черновой перевод ИИ

Sheet Справочники
A1: country | B1: publish | C1: status | D1: cat | E1: reg | F1: s_acc | G1: s_diff | H1: s_when | I1: yes_no | J1: ticket_type | K1: ticket_status | L1: priority | M1: license
A2: country | B2: publish | C2: status | D2: cat | E2: reg | F2: s_acc | G2: s_diff | H2: s_when | I2: yes_no | J2: ticket_type | K2: ticket_status | L2: priority | M2: license
A3: kg | B3: опубликовано | C3: Координаты уточняются | D3: Автодорога | E3: Алтайский край (рядом) | F3: Кроссовер | G3: Высокая | H3: Апр – июн | I3: да | J3: Новое место | K3: открыт | L3: высокий | M3: CC (Wikimedia Commons, через tonkosti.ru) — точную версию лицензии сверить на Commons
A4: alt | B4: черновик | C4: Нужна проверка | D4: Альпинистский лагерь | E4: Баткенская область | F4: На любой машине | G4: Лёгкая | H4: Апр – ноя | I4: нет | J4: Дозаполнить данные | K4: в работе | L4: средний | M4: CC BY 2.0
B5: скрыто | C5: Проверено | D5: Археологический памятник | E5: Джалал-Абадская область | F5: Нужен 4×4 | G5: Лёгкая–средняя | H5: Апр – окт | J5: Проверить факты | K5: на проверке | L5: низкий | M5: CC BY 2.5
D6: Водопад | E6: Иссык-Кульская область | F6: По воде | G6: Очень лёгкая | H6: Апр – сен | J6: Уточнить координаты | K6: готово | M6: CC BY 3.0
D7: Водопад; памятник природы республиканского значения | E7: Нарынская область | F7: Только пешком | G7: Сложная | H7: Дек – июн | J7: Фото | K7: отклонён | M7: CC BY 4.0
D8: Водохранилище | E8: Ошская область | G8: См. описание | H8: Июл – сен | J8: Перевод EN | M8: CC BY-SA 2.0
D9: Высокогорное плато | E9: Республика Алтай | G9: Средняя | H9: Июн | J9: Отзыв/жалоба | M9: CC BY-SA 2.5
D10: Гора / озеро | E10: Таласская область | G10: Средняя–высокая | H10: Июн – авг | J10: Другое | M10: CC BY-SA 3.0
D11: Горная долина / Горячие источники | E11: Чуйская область | G11: Средняя–сложная | H11: Июн – окт | M11: CC BY-SA 3.0 de
D12: Горная хижина | H12: Июн – сен | M12: CC BY-SA 4.0
D13: Городище | H13: Круглый год | M13: CC0
D14: Горячие источники | H14: Май – авг | M14: Flickr — лицензию сверить (вероятно CC), права не проверены
D15: Долина | H15: Май – июн | M15: Pixabay Content License
D16: Долина / жайлоо | H16: Май – окт | M16: Public Domain (по данным altapress/kp для фото HiOr) — сверить
D17: Долина / панорама | H17: Май – сен | M17: Public domain
D18: Долина / перевал | H18: Мар – май | M18: Unsplash License
D19: Исторический / духовный объект | H19: Ноя – апр | M19: © Global Look Press
D20: Исторический комплекс | H20: Ноя – сен | M20: © Greenpeace / altapress.ru
D21: Каньон | H21: Сен – июл | M21: © Shutterstock (через Tripster)
D22: Караван-сарай | H22: Сен – окт | M22: © Shutterstock (через tonkosti.ru)
D23: Культурный центр | H23: Янв – апр | M23: © Shutterstock (через tonkosti.ru), права не проверены
D24: Курорт / озеро (всесезонный горнолыжный курорт; озеро — памятник природы) | M24: © Shutterstock / права не проверены
D25: Ледник | M25: © TURISTKA.RU
D26: Ледниковое озеро | M26: © Алтай-Фото
D27: Лес | M27: © Алтайский заповедник / altapress, права не проверены
D28: Мавзолей | M28: © ГАГУ, права не проверены
D29: Мечеть | M29: © КП, права не проверены
D30: Музей | M30: © Комсомольская правда
D31: Музей (краеведческий, археология, этнография, природа, искусство) | M31: © Правительство Алтайского края, права не проверены
D32: Национальный парк | M32: © автор / Т—Ж, права не проверены
D33: Озеро | M33: © автор, права не проверены
D34: Озеро (каскад горных озёр); памятник природы | M34: © администрация Улаганского р-на, права не проверены
D35: Озеро (каскад горных озёр); частично Катунский биосферный заповедник (ЮНЕСКО «Золотые горы Алтая»), Нижнее и Среднее — региональные памятники природы | M35: © парк «Уч Энмек», права не проверены
... D37: Перевал | M37: права не проверены
D38: Петроглифы
D39: Пещеры
D40: Природный памятник
D41: Природный парк
...

Sheet _шаблон
A1: #title | B1: Новое место | C1: · ← к оглавлению
A2: #section | B2: Основное
A3: id | B3: ID места (kg-…, alt-…)
A4: country | B4: Страна (kg / alt)
A5: publish | B5: Публикация | C5: черновик
A6: status | B6: Статус проверки | C6: Нужна проверка
A7: name | B7: Название
A8: full | B8: Полное название
A9: cat | B9: Категория
A10: reg | B10: Регион
A11: dist | B11: Район
A12: lat | B12: Широта
A13: lon | B13: Долгота
A14: elev | B14: Высота
A15: near | B15: Ближайший пункт
A16: tags | B16: Теги (через ;)
A17: top | B17: В топе (да/нет)
A18: rank | B18: Место в рейтинге
... A43: #table:photos | B43: Фото — 0
A44: #keys | C44: f | D44: t | E44: w | F44: h | G44: cap | H44: by | I44: lic | J44: page
A45: #labels | B45: № / строки ниже | C45: Файл (img/…) | D45: Миниатюра (img/t_…) | E45: Ширина | F45: Высота | G45: Подпись | H45: Автор | I45: Лицензия | J45: Страница-источник
A47: #table:videos | B47: Видео — 0
A48: #keys | C48: t | D48: u | E48: ch | F48: y
A49: #labels | B49: № / строки ниже | C49: Заголовок | D49: Ссылка | E49: Канал | F49: Год
A51: #table:photo_links | B51: Фото-ссылки (внешние) — 0
A52: #keys | C52: cap | D52: url | E52: by
A53: #labels | B53: № / строки ниже | C53: Подпись | D53: Ссылка | E53: Автор
A56: #section | B56: Дорога
A57: how | B57: Как добраться (кратко)
A58: needcar | B58: Нужна ли машина
A59: self | B59: Самостоятельно / с гидом
A60: roadtype | B60: Тип дороги
A61: traveltime | B61: Время в пути
A62: transfer | B62: Трансфер
A63: p_sum | B63: Дорога: сводка
A64: #table:routes | B64: Подъезды — 0
A65: #keys | C65: rec | D65: title | E65: from | F65: route | G65: km | H65: time | I65: surface | J65: vehicle | K65: season | L65: last | M65: parking_d | N65: parking_price | O65: trail_d | P65: haz | Q65: src | R65: hub | S65: hub_lat | T65: hub_lon | U65: rkm | V65: parking_lat | W65: parking_lon | X65: trail_lat | Y65: trail_lon | Z65: road | AA65: has_rt
A66: #labels | B66: № / строки ниже | C66: Рекомендован (да/нет) | D66: Название варианта | E66: Откуда | F66: Маршрут | G66: Км | H66: Время | I66: Покрытие | J66: Машина | K66: Сезон | L66: Последние АЗС/магазины | M66: Парковка | N66: Парковка: цена | O66: Тропа от парковки | P66: Опасности | Q66: Источник | R66: Город-старт | S66: Старт: широта | T66: Старт: долгота | U66: Км по графу дорог | V66: Парковка: широта | W66: Парковка: долгота | X66: Тропа: широта | Y66: Тропа: долгота | Z66: Геометрия дороги (JSON, генерируется) | AA66: Есть маршрут на карте (да/нет)
A68: #table:transport | B68: Транспорт и туры — 0
A69: #keys | C69: mode | D69: provider | E69: from | F69: details | G69: price | H69: year | I69: contact | J69: src
...

Sheet kg-skazka
A1: #title | B1: Каньон Сказка | C1: kg-skazka · ← к оглавлению
A2: #section | B2: Основное
A3: id | B3: ID места (kg-…, alt-…) | C3: kg-skazka
A4: country | B4: Страна (kg / alt) | C4: kg
A5: publish | B5: Публикация | C5: опубликовано
A6: status | B6: Статус проверки | C6: Проверено
A7: name | B7: Название | C7: Каньон Сказка
A8: full | B8: Полное название | C8: Каньон Сказка (Skazka / Fairy Tale Canyon)
A9: cat | B9: Категория | C9: Каньон
A10: reg | B10: Регион | C10: Иссык-Кульская область
A11: dist | B11: Район | C11: Джети-Огузский район
A12: lat | B12: Широта | C12: 42.1565
A13: lon | B13: Долгота | C13: 77.3543
A14: elev | B14: Высота | C14: ≈1650–1700 м (расчёт: уровень Иссык-Куля 1607 м, каньон на первой террасе над южным берегом; точная отметка входа источниками не опубликована)
A15: near | B15: Ближайший пункт | C15: Тосор (≈8 км на восток от поворота, 10–15 мин на машине). Поворот к каньону — примерно 4 км западнее Тосора на трассе Балыкчи — Каракол (южный берег), ≈120-й км от Балыкчи.
A16: tags | B16: Теги (через ;) | C16: canyons;any-car;easy;no-car;year-round;hiking;yurts
A17: top | B17: В топе (да/нет) | C17: нет
A18: rank | B18: Место в рейтинге | C18: 25
A19: updated_at | B19: Изменено (дата)
A20: updated_by | B20: Кто изменил
A22: #section | B22: Коротко на карточке (плашки)
A23: months | B23: Месяцы сезона (1;2;…12) | C23: 1;2;3;4;5;6;7;8;9;10;11;12
A24: month_scores | B24: Оценка месяцев (JSON: месяц → 2 лучшее, 1 подходит), напр. {"6":1,"7":2} | C24: {"1":1,"2":1,"3":1,"4":1,"5":2,"6":2,"7":1,"8":1,"9":2,"10":2,"11":1,"12":1}
A25: s_diff | B25: Сложность (коротко) | C25: Лёгкая
A26: s_when | B26: Когда (коротко) | C26: Круглый год
A27: s_acc | B27: Доступ (коротко) | C27: На любой машине
A28: s_onsite | B28: Время на месте (коротко) | C28: 40 мин
A29: s_entry | B29: Вход (коротко) | C29: 50 сомов с человека
A30: s_net | B30: Связь (коротко) | C30: У трассы и в…
A31: rating_v | B31: Рейтинг | C31: 4.8
A32: rating_n | B32: Кол-во оценок | C32: 1682
A33: rating_src | B33: Источник рейтинга | C33: Google
A35: #section | B35: Обзор — тексты
A36: short | B36: Коротко (1–2 предложения) | C36: Небольшой каньон из разноцветных глин и песчаников на южном берегу Иссык-Куля между Тосором и Каджи-Саем. Красные, оранжевые, жёлтые и серые гребни; осмотр занимает 1–2 часа, виды на озеро и хребет Терскей-Ала-Тоо с верхних точек.
A37: desc | B37: Описание | C37: Сказка — компактный эрозионный каньон на первой террасе над южным берегом Иссык-Куля, в ≈2 км от трассы Балыкчи — Каракол (поворот примерно на 120-м км от Балыкчи, большой указатель; рядом второй указатель «Jeti-Oguz», у шлагбаума берут плату). Ветер и дождь вырезали в красных и охристых глинах стены, башни, «печные трубы» в духе Каппадокии; самый известный гребень называют «Китайской стеной». По каньону расходится сеть тропинок: короткий круг — около часа, расширенный маршрут со смотровыми площадками — около двух; набор высоты небольшой. С гребней открывается вид на озеро. Снега здесь почти не бывает, поэтому каньон доступен круглый год, но летом в полдень очень жарко, а после дождя глина становится скользкой. Инфраструктуры минимум: будка кассира у шлагбаума, парковка, простой туалет.
A38: guide | B38: Почему стоит приехать / текст аудиогида | C38: Иди не по одной тропе, а поднимись на гребень: именно сверху «Китайская стена» превращается в зубчатую линию, а за ней раскрывается синяя полоса Иссык-Куля. Ищи фигуры сам — путешественники видят здесь дракона, пингвина, замки и спящего великана, и у каждого выходит своя сказка; официальных табличек нет. Лучший свет — рассвет и час перед закатом, когда красные слои загораются, а серые уходят в тень; в обед цвета выгорают, а тени нет совсем. Возьми обувь с протектором: сыпучий песчаник скользит даже в сухую погоду, а после дождя в каньон лучше не ходить. Если осталось время, спустись к берегу — пляж у Тосора считают одним из красивейших на южном берегу.
A39: see | B39: Что посмотреть | C39: Гребень «Китайская стена»; «расписные горы» с жёлто-оранжево-розовыми слоями; «печные трубы» и башни; смотровые точки на гребнях с видом на Иссык-Куль и Терскей-Ала-Тоо; «окна» в скалах. Фигуры дракона, пингвина, замков — условные туристические названия, табличек нет.
A40: skip | B40: Кому не стоит | C40: Если ты уже был в Чарынском каньоне или на «Марсе» у Каджи-Сая и ждёшь масштаба — Сказка заметно меньше. Если на улице ливень или гроза — глина скользкая, сухие русла опасны. Если едешь в полдень в июле без шляпы и воды — тени здесь нет вообще.
A42: #section | B42: Медиа
A43: #table:photos | B43: Фото — 2
...

Sheet kg-altyn-arashan
A1: #title | B1: Алтын-Арашан | C1: kg-altyn-arashan · ← к оглавлению
A2: #section | B2: Основное
A3: id | B3: ID места (kg-…, alt-…) | C3: kg-altyn-arashan
A4: country | B4: Страна (kg / alt) | C4: kg
A5: publish | B5: Публикация | C5: опубликовано
A6: status | B6: Статус проверки | C6: Проверено
A7: name | B7: Название | C7: Алтын-Арашан
A8: full | B8: Полное название | C8: Алтын-Арашан (долина реки Арашан, горячие источники)
A9: cat | B9: Категория | C9: Горная долина / Горячие источники
A10: reg | B10: Регион | C10: Иссык-Кульская область
A11: dist | B11: Район | C11: Ак-Суйский район
A12: lat | B12: Широта | C12: 42.373
A13: lon | B13: Долгота | C13: 78.612
A14: elev | B14: Высота | C14: ≈2435–2600 м: трек-платформы (loc.wiki/AllTrails) дают 2350–2435 м у гостевых домов, Too.kg и Visit Kyrgyzstan — 2600 м у источников; Nomad's Land — 2580 м. Значение «3000 м» у некоторых сайтов завышено.
A15: near | B15: Ближайший пункт | C15: Ак-Суу (бывш. Теплоключенка), ≈10–12 км восточнее Каракола; от Ак-Суу до источников ≈15 км вверх по ущелью
A16: tags | B16: Теги (через ;) | C16: valleys;4x4;medium;top;no-car;hiking;horses;yurts
A17: top | B17: В топе (да/нет) | C17: да
A18: rank | B18: Место в рейтинге | C18: 11
A19: updated_at | B19: Изменено (дата)
A20: updated_by | B20: Кто изменил
A22: #section | B22: Коротко на карточке (плашки)
A23: months | B23: Месяцы сезона (1;2;…12) | C23: 6;7;8;9;10
A24: month_scores | B24: Оценка месяцев (JSON: месяц → 2 лучшее, 1 подходит), напр. {"6":1,"7":2}
A25: s_diff | B25: Сложность (коротко) | C25: Средняя
A26: s_when | B26: Когда (коротко) | C26: Июн – окт
A27: s_acc | B27: Доступ (коротко) | C27: Нужен 4×4
A28: s_onsite | B28: Время на месте (коротко) | C28: 3–5 ч вверх, ≈4 ч…
A29: s_entry | B29: Вход (коротко) | C29: Въезд в ущелье Арашан
A30: s_net | B30: Связь (коротко) | C30: Мобильной связи в…
A31: rating_v | B31: Рейтинг | C31: 4.8
A32: rating_n | B32: Кол-во оценок | C32: 706
A33: rating_src | B33: Источник рейтинга | C33: Google
A35: #section | B35: Обзор — тексты
A36: short | B36: Коротко (1–2 предложения) | C36: Высокогорная долина с радоновыми и сероводородными горячими источниками (35–41 °C), реликтовым еловым лесом и видом на трапецию пика Палатка (4260 м). От Ак-Суу — 15 км пешком (3–5 ч) или 1,5–2,5 ч на УАЗе по одной из самых тяжёлых дорог Прииссыккулья.
A37: desc | B37: Описание | C37: Алтын-Арашан («золотой источник») — долина реки Арашан над селом Ак-Суу, с 1963 года — природный заказник. У слияния рек стоит горстка гостевых домов и юрточных лагерей, у каждого — своя купальня: радоновая вода 35 °C и сероводородная 41 °C круглый год; есть и «дикие» каменные ванны у реки. Над долиной господствует пик Палатка (Аксуйская стена, 4260 м). Дорога от Ак-Суу — 15 км каменистого подъёма с бродами: обычные машины и прокатные авто сюда не пускают, ездят УАЗ-469/«буханки», ГАЗ-66, Nissan Patrol с местными водителями; пешком — 3–5 ч при наборе ≈600 м, тропа простая и очевидная. Отсюда начинается или заканчивается классический трек через перевал Ала-Куль (3900 м) в Каракольское ущелье, а в 5 км выше курорта уходит приток к озеру. Электричество — от генераторов и солнца, оплата только наличными, мобильная связь практически отсутствует. Ночью даже летом бывает −2…−5 °C.
A38: guide | B38: Почему стоит приехать / текст аудиогида | C38: Поднимайся пешком, а вниз возьми «буханку» — так увидишь и ущелье, и получишь порцию экстрима на камнях и бродах, из-за которых прокатные компании запрещают сюда заезжать. Купальни принадлежат разным гостевым домам: у кого-то деревянный сруб с сероводородной водой 41 °C, у кого-то бесплатная каменная ванна прямо у реки — пройдись и выбери. Вечером, когда туристы однодневных туров уезжают, долина остаётся тем немногим, кто ночует: смотри на Палатку в закатном свете и на звёзды без городской засветки. Возьми наличные сомы и тёплый спальник: карт не принимают, а ночью холодно даже в июле. Если планируешь Ала-Куль — не делай его «за день из купальни»: перевал 3900 м требует акклиматизации и отдельного дня.
A39: see | B39: Что посмотреть | C39: Горячие купальни при гостевых домах (радон 35 °C, сероводород 41 °C) и «дикие» ванны у реки; пик Палатка / Аксуйская стена (4260 м); реликтовый тянь-шаньский еловый лес; верховья долины Арашан и приток к Ала-Кулю; юрточные лагеря; зимой — заснеженная долина (доступ только на УАЗе или пешком).
A40: skip | B40: Кому не стоит | C40: Если у тебя один день и больная спина — 2,5 ч тряски на УАЗе в одну сторону тебя не порадуют. Если ждёшь спа-курорт с инфраструктурой — здесь срубы, генераторы и уличные туалеты. Если едешь на прокатной легковушке — въезд в ущелье договором проката обычно запрещён.
A42: #section | B42: Медиа
A43: #table:photos | B43: Фото — 2
...

Sheet kg-son-kul
A1: #title | B1: Сон-Куль | C1: kg-son-kul · ← к оглавлению
A2: #section | B2: Основное
A3: id | B3: ID места (kg-…, alt-…) | C3: kg-son-kul
A4: country | B4: Страна (kg / alt) | C4: kg
A5: publish | B5: Публикация | C5: опубликовано
A6: status | B6: Статус проверки | C6: Проверено
A7: name | B7: Название | C7: Сон-Куль
A8: full | B8: Полное название | C8: Озеро Сон-Куль (Сонкёль)
A9: cat | B9: Категория | C9: Озеро
A10: reg | B10: Регион | C10: Нарынская область
A11: dist | B11: Район | C11: Единой административной принадлежности в источниках не…
A12: lat | B12: Широта | C12: 41.841
A13: lon | B13: Долгота | C13: 75.155
A14: elev | B14: Высота | C14: 3016 м над уровнем моря (map.kg, asiamountains.net, Ak-Sai, Caravanistan); Too.kg округляет до 3000 м.
A15: near | B15: Ближайший пункт | C15: Постоянных сёл на берегу нет. Базы: Кочкор (через Калмак-Ашуу, ~3 ч), село Кызарт (старт конных маршрутов), Сары-Булак, Нарын (~90 км к юго-востоку по прямой, через Терскей-Торпок), с юго-запада — Ак-Талаа/Баетов (Молдо-Ашуу) и Чаек/Кызыл-Кия (Кара-Кече).
A16: tags | B16: Теги (через ;) | C16: lakes;any-car;medium;top;free;no-car;hiking;horses;yurts
A17: top | B17: В топе (да/нет) | C17: да
A18: rank | B18: Место в рейтинге | C18: 13
A19: updated_at | B19: Изменено (дата)
A20: updated_by | B20: Кто изменил
A22: #section | B22: Коротко на карточке (плашки)
A23: months | B23: Месяцы сезона (1;2;…12) | C23: 5;6;7;8;9;10
A24: month_scores | B24: Оценка месяцев (JSON: месяц → 2 лучшее, 1 подходит), напр. {"6":1,"7":2} | C24: {"5":1,"6":1,"7":2,"8":2,"9":1,"10":1}
A25: s_diff | B25: Сложность (коротко) | C25: Средняя
A26: s_when | B26: Когда (коротко) | C26: Май – окт
A27: s_acc | B27: Доступ (коротко) | C27: На любой машине
A28: s_onsite | B28: Время на месте (коротко) | C28: 2 дня
A29: s_entry | B29: Вход (коротко) | C29: Бесплатно
A30: s_net | B30: Связь (коротко) | C30: Связь только местами
A31: rating_v | B31: Рейтинг | C31: 4.9
A32: rating_n | B32: Кол-во оценок | C32: 382
A33: rating_src | B33: Источник рейтинга | C33: Google
A35: #section | B35: Обзор — тексты
A36: short | B36: Коротко (1–2 предложения) | C36: Второе по величине озеро Кыргызстана на высоте 3016 м среди бескрайнего джайлоо: летом — юрточные лагеря, табуны лошадей и отары, зимой — безлюдная ледяная равнина.
A37: desc | B37: Описание | C37: Сон-Куль — пресное высокогорное озеро во Внутреннем Тянь-Шане между хребтами Сонкуль-Тоо (север) и Молдо-Тоо (юг): около 29 км в длину и 17–18 км в ширину, площадь ~278 км², глубина до 13–14 м (по map.kg — до 22 м). В озеро впадает 18 ручьёв, вытекает одна река Сон-Куль. Ледостав — со второй половины октября–ноября до конца апреля. До 1959 года рыбы в озере не было; сейчас здесь сиг, пелядь, голый осман. Часть акватории входит в заказник Каратал-Жапырык (1994), озеро — Рамсарское водно-болотное угодье (2011): летом здесь гнездятся до 66 видов водоплавающих, включая краснокнижного горного гуся. Пастбища вокруг (~108 тыс. га) — одни из главных летних джайлоо страны; постоянных посёлков нет, с июня по сентябрь работают около 15 юрточных лагерей. На северном берегу — каменный мавзолей Тайлак-баатыра конца XIX века.
A38: guide | B38: Почему стоит приехать / текст аудиогида | C38: Ночуй минимум одну ночь: главное на Сон-Куле — закат над водой, звёздное небо без засветки и утренний туман над джайлоо. Возьми лошадь у хозяев лагеря (около 700 сом в день) и прокатись вдоль берега к табунам, попробуй свежий кумыс и посмотри, как доят кобылиц. Если есть 2–3 дня, приходи верхом из Кызарта через Килемче и перевал Джалгыз-Карагай (3400 м) — так озеро открывается сверху, как его видели кочевники. На северном берегу найди мавзолей Тайлак-баатыра. Даже в июле ночью бывает мороз — спальник и пуховка обязательны.
A39: see | B39: Что посмотреть | C39: Закат и звёздное небо над озером; табуны и юрты чабанов на джайлоо; дойку кобылиц и приготовление кумыса; гнездящихся водоплавающих птиц (горный гусь, журавли, лебеди) — Рамсарское угодье; мавзолей Тайлак-баатыра на северном берегу; серпантины перевалов Калмак-Ашуу, Молдо-Ашуу («33 попугая» — Терскей-Торпок); каскад Кок-Джерты на реке Сон-Куль (4 км ниже истока); зимой — ледяное озеро (зимний юрточный лагерь ставится ежегодно — Caravanistan).
A40: skip | B40: Кому не стоит | C40: У тебя всего один день — дорога туда и обратно из Кочкора займёт 6–7 часов, а смысл места в ночёвке. Ты плохо переносишь высоту 3000 м и ночные заморозки и не готов к удобствам на улице. Ты едешь в октябре–мае без зимней экспедиционной подготовки — лагерей нет, перевалы под снегом.
A42: #section | B42: Медиа
A43: #table:photos | B43: Фото — 2
...

Sheet kg-0002
A1: #title | B1: Ущелье Кара-Булак | C1: kg-0002 · ← к оглавлению
A2: #section | B2: Основное
A3: id | B3: ID места (kg-…, alt-…) | C3: kg-0002
A4: country | B4: Страна (kg / alt) | C4: kg
A5: publish | B5: Публикация | C5: опубликовано
A6: status | B6: Статус проверки | C6: Проверено
A7: name | B7: Название | C7: Ущелье Кара-Булак
A8: full | B8: Полное название | C8: Ущелье Кара-Булак
A9: cat | B9: Категория | C9: Ущелье
A10: reg | B10: Регион | C10: Чуйская область
A11: dist | B11: Район | C11: Аламудунский район Чуйской области
A12: lat | B12: Широта | C12: 42.679407
A13: lon | B13: Долгота | C13: 74.622574
A14: elev | B14: Высота | C14: Около 1800 м у экорезорта Kara Bulak (sxodim, karabulak.kg); склоны ущелья выше. Соседняя гора Тыша — 2300 м (hiking.kg).
A15: near | B15: Ближайший пункт | C15: Сёла Арашан и Кой-Таш (подъезд через урочище Татыр); Бишкек — 25–27 км (sxodim, triptokyrgyzstan).
A16: tags | B16: Теги (через ;) | C16: gorges;any-car;easy;year-round;hiking;horses
A17: top | B17: В топе (да/нет) | C17: нет
A18: rank | B18: Место в рейтинге | C18: 78
A19: updated_at | B19: Изменено (дата)
A20: updated_by | B20: Кто изменил
A22: #section | B22: Коротко на карточке (плашки)
A23: months | B23: Месяцы сезона (1;2;…12) | C23: 1;2;3;4;5;6;7;8;9;10;11;12
A24: month_scores | B24: Оценка месяцев (JSON: месяц → 2 лучшее, 1 подходит), напр. {"6":1,"7":2}
A25: s_diff | B25: Сложность (коротко) | C25: Лёгкая
A26: s_when | B26: Когда (коротко) | C26: Круглый год
A27: s_acc | B27: Доступ (коротко) | C27: На любой машине
A28: s_onsite | B28: Время на месте (коротко) | C28: 2 ч 25 мин
A29: s_entry | B29: Вход (коротко) | C29: Отдельного входного…
A30: s_net | B30: Связь (коротко) | C30: На территории…
A31: rating_v | B31: Рейтинг
A32: rating_n | B32: Кол-во оценок
A33: rating_src | B33: Источник рейтинга
A35: #section | B35: Обзор — тексты
A36: short | B36: Коротко (1–2 предложения) | C36: Небольшое ущелье в Кыргызском Ала-Тоо в 25–27 км от Бишкека, над урочищем Татыр: цветные скалы, родники, водопад и панорамы Чуйской долины; в ущелье — экорезорт Kara Bulak.
A37: desc | B37: Описание | C37: Кара-Булак («чёрный родник») — ущелье в предгорьях Кыргызского Ала-Тоо между Аламединским ущельем и Чункурчаком. Triptokyrgyzstan описывает цветные скалы, зелёные холмы, водопад, множество родников и ручьёв и панорамы Бишкека, Чуйской долины и снежных вершин. Подъезд — по дороге через Татыр в сторону Чункурчака (в 2026 г. её асфальтируют) и далее крутым серпантином через перевальчик. Основную часть ущелья занимает частный экорезорт Kara Bulak (2ГИС 4.8/5, 903 оценки): коттеджи, кафе национальной кухни, баня, конные прогулки. Окрестности подходят для пеших и конных прогулок; рядом — гора Тыша, «Небесный мост» и Голубиный водопад по дороге к Алтын-Тёру.
A38: guide | B38: Почему стоит приехать / текст аудиогида | C38: Кара-Булак — ближайший к Бишкеку «горный выходной»: всего час на машине, а вид на Чуйскую долину сверху как с самолёта. Самая живописная часть — серпантин после Татыра: остановись на перевальчике до спуска в ущелье. Ущелье во многом занято частным экорезортом, поэтому для прогулки по его территории и конной поездки (700 сом/час по данным 2022 г.) договорись с ресепшеном. Если хочется просто погулять — поднимись на соседнюю гору Тыша (6 км, ~2,5 часа, +540 м).
A39: see | B39: Что посмотреть | C39: Цветные скалы и родники ущелья, водопад (triptokyrgyzstan); панорамы Бишкека и Чуйской долины с серпантина; по пути — «Небесный мост» и Голубиный водопад (hiking.kg); гора Тыша (2300 м) с видом на город и хребет.
A40: skip | B40: Кому не стоит | C40: Ты ищешь дикое ущелье без инфраструктуры — здесь доминирует частный курорт. Нет машины: общественного транспорта до ущелья нет. Хочешь высокогорье и ледники — лучше Ала-Арча или Аламедин.
A42: #section | B42: Медиа
A43: #table:photos | B43: Фото — 0
...

Sheet kg-0003
A1: #title | B1: Национальный парк Ала-Арча | C1: kg-0003 · ← к оглавлению
A2: #section | B2: Основное
A3: id | B3: ID места (kg-…, alt-…) | C3: kg-0003
A4: country | B4: Страна (kg / alt) | C4: kg
A5: publish | B5: Публикация | C5: опубликовано
A6: status | B6: Статус проверки | C6: Проверено
A7: name | B7: Название | C7: Национальный парк Ала-Арча
A8: full | B8: Полное название | C8: Национальный парк Ала-Арча
A9: cat | B9: Категория | C9: Национальный парк
A10: reg | B10: Регион | C10: Чуйская область
A11: dist | B11: Район | C11: Аламудунский район
A12: lat | B12: Широта | C12: 42.64484
A13: lon | B13: Долгота | C13: 74.48032
A14: elev | B14: Высота | C14: От ~1500 м в нижней части ущелья до 4895 м (пик Семёнова-Тян-Шанского) — asiamixtravel 2026. Ориентиры маршрутов: водопад Ак-Сай ~2860 м, хижина Рацека ~3380 м (adventuresoflilnicki, 16.09.2026); стартовая зона у альплагеря — около 2150 м (расчёт: водопад 2860 м минус набор 700 м по hiking.kg).
A15: near | B15: Ближайший пункт | C15: Кашка-Суу (адрес парка в 2ГИС)
A16: tags | B16: Теги (через ;) | C16: parks;any-car;hard;top;no-car;hiking;horses;yurts
A17: top | B17: В топе (да/нет) | C17: да
A18: rank | B18: Место в рейтинге | C18: 1
A19: updated_at | B19: Изменено (дата)
A20: updated_by | B20: Кто изменил
A22: #section | B22: Коротко на карточке (плашки)
A23: months | B23: Месяцы сезона (1;2;…12) | C23: 5;6;7;8;9;10
A24: month_scores | B24: Оценка месяцев (JSON: месяц → 2 лучшее, 1 подходит), напр. {"6":1,"7":2} | C24: {"5":1,"6":1,"7":2,"8":2,"9":2,"10":1}
A25: s_diff | B25: Сложность (коротко) | C25: Сложная
A26: s_when | B26: Когда (коротко) | C26: Май – окт
A27: s_acc | B27: Доступ (коротко) | C27: На любой машине
A28: s_onsite | B28: Время на месте (коротко) | C28: 40 мин в одну…
A29: s_entry | B29: Вход (коротко) | C29: С 11
A30: s_net | B30: Связь (коротко) | C30: У КПП и альплагеря…
A31: rating_v | B31: Рейтинг | C31: 4.7
A32: rating_n | B32: Кол-во оценок | C32: 3871
A33: rating_src | B33: Источник рейтинга | C33: Google
A35: #section | B35: Обзор — тексты
A36: short | B36: Коротко (1–2 предложения) | C36: Ала-Арча — государственный природный парк в ущелье Кыргызского Ала-Тоо в ~40 км к югу от Бишкека: еловые и арчовые леса, ледники и вершины до 4895 м, самые популярные однодневные треки страны.
A37: desc | B37: Описание | C37: Ала-Арча — горный природный парк в Аламудунском районе Чуйской области, в одноимённом ущелье реки Ала-Арча на северном склоне Кыргызского Ала-Тоо. Высоты — от ~1500 м до 4895 м; в верховьях ледники Ак-Сай, Адыгене и др., на склонах — ели Шренка и арча, давшая имя ущелью. С 1 мая 2025 г. по поручению президента в парк запрещён въезд машин с ДВС: гостей оставляют на парковке у КПП (≈700 мест), а дальше бесплатно возят ~80 электробусов (около 12 км до альплагеря и начала троп). На территории — ресторан, кафе, коттеджи, юрточный городок, газовые мангалы (костры и шашлык на дровах запрещены). Классические маршруты — водопад Ак-Сай (4,3 км, +700 м), хижина Рацека (~3380 м) у ледника Ак-Сай, ущелье Адыгене; зимой рядом работает горнолыжная база.
A38: guide | B38: Почему стоит приехать / текст аудиогида | C38: Ала-Арча — лучший способ за один день из Бишкека попасть в настоящие высокие горы: садись на автобус №1 у площади Усубалиева и через час ты у КПП. Дальше бесплатный электробус довезёт до альплагеря — оттуда стартуют все тропы. Для первого раза хватит водопада Ак-Сай: 4,3 км и +700 м, около 2,5 часа вверх, с видом на ледниковый цирк. Если хорошо акклиматизирован — продолжи к хижине Рацека (~3380 м), но выходи рано: после обеда в горах часто портится погода. Костры запрещены, так что бери термос и перекус или обедай в кафе у альплагеря.
A39: see | B39: Что посмотреть | C39: Прогулочные участки вдоль Ала-Арчи, альплагерь, водопад Ак-Сай; хижина Рацека — отдельный более трудный поход.
A40: skip | B40: Кому не стоит | C40: Ты уже ходил в похожие ущелья (Аламедин, Кегеты) и ищешь безлюдье — в выходные здесь многолюдно. Тебе нужна поездка на своей машине до троп — с мая 2025 г. внутрь пускают только электромобили. Не готов к набору 700+ м даже на «лёгкий» водопад.
A42: #section | B42: Медиа
A43: #table:photos | B43: Фото — 2
...

Sheet kg-0004
A1: #title | B1: Озеро Тулпар-Куль | C1: kg-0004 · ← к оглавлению
A2: #section | B2: Основное
A3: id | B3: ID места (kg-…, alt-…) | C3: kg-0004
A4: country | B4: Страна (kg / alt) | C4: kg
A5: publish | B5: Публикация | C5: опубликовано
A6: status | B6: Статус проверки | C6: Проверено
A7: name | B7: Название | C7: Озеро Тулпар-Куль
A8: full | B8: Полное название | C8: Озеро Тулпар-Куль
A9: cat | B9: Категория | C9: Озеро
A10: reg | B10: Регион | C10: Ошская область
A11: dist | B11: Район | C11: Алайский район Ошской области
A12: lat | B12: Широта | C12: 39.505431
A13: lon | B13: Долгота | C13: 72.935057
A14: elev | B14: Высота | C14: Около 3500 м (too.kg; у юрточного лагеря — sarymogol.com). Утверждение Visit Alay о «той же высоте, что и базовый лагерь» не принято как точная отметка.
A15: near | B15: Ближайший пункт | C15: Сары-Могол — около 25 км к северо-западу (Visit Alay, Backpack Adventures); база для трансферов, лошадей и CBT. Также доступ верхом из Кашка-Суу (too.kg).
A16: tags | B16: Теги (через ;) | C16: lakes;any-car;easy;top;no-car;hiking;horses;yurts
A17: top | B17: В топе (да/нет) | C17: да
A18: rank | B18: Место в рейтинге | C18: 10
A19: updated_at | B19: Изменено (дата)
A20: updated_by | B20: Кто изменил
A22: #section | B22: Коротко на карточке (плашки)
A23: months | B23: Месяцы сезона (1;2;…12) | C23: 5;6;7;8;9;10
A24: month_scores | B24: Оценка месяцев (JSON: месяц → 2 лучшее, 1 подходит), напр. {"6":1,"7":2} | C24: {"5":1,"6":2,"7":2,"8":2,"9":1,"10":1}
A25: s_diff | B25: Сложность (коротко) | C25: Лёгкая
A26: s_when | B26: Когда (коротко) | C26: Май – окт
A27: s_acc | B27: Доступ (коротко) | C27: На любой машине
A28: s_onsite | B28: Время на месте (коротко) | C28: 5–8 ч
A29: s_entry | B29: Вход (коротко) | C29: Входного билета нет
A30: s_net | B30: Связь (коротко) | C30: Конкретное покрытие…
A31: rating_v | B31: Рейтинг | C31: 4.9
A32: rating_n | B32: Кол-во оценок | C32: 38
A33: rating_src | B33: Источник рейтинга | C33: Google
A35: #section | B35: Обзор — тексты
A36: short | B36: Коротко (1–2 предложения) | C36: Тулпар-Куль — высокогорное озеро (~3500 м) в Алайской долине, в шаговой доступности от базового лагеря пика Ленина (7134 м), с юрточными лагерями на берегу.
A37: desc | B37: Описание | C37: Тулпар-Куль (Тулпар-Кёл) — довольно большое прозрачное озеро на высоте около 3500 м у подножия Заалайского хребта, в шаговой доступности от Ачык-Таша — базового лагеря пика Ленина (too.kg). В тихую погоду в нём отражается пик Ленина (7134 м). До озера 25 км от села Сары-Могол: около 45 мин на машине, 4–5 ч верхом или 8–9 ч пешком (Visit Alay). Летом на берегу работают юрточные лагеря CBT и частных хозяев (от 1000 сом за ночь с завтраком и ужином — Visit Alay). От озера начинаются однодневные треки к «Перевалу путешественников» (~4100 м) и к языку ледника Ленина, многодневные — на пик Юхина и Раздельную (Visit Alay, CBT). Район в пограничной зоне — нужен пропуск (Visit Alay).
A38: guide | B38: Почему стоит приехать / текст аудиогида | C38: Приходи к озеру рано утром: в штиль пик Ленина отражается в воде, а после обеда погода в Заалае часто портится (отзывы TripAdvisor). Ночуй в юрте на берегу — от 1000 сом с ужином и завтраком (Visit Alay) — и на следующий день поднимись на «Перевал путешественников» (~4100 м): 3 ч вверх, 2 ч вниз и панорама всей стены Ленина. Не забудь пограничный пропуск — оформление занимает 10–20 дней (Visit Alay). Если попадёшь на третьи выходные июля, в Сары-Моголе проходит фестиваль конных и ячьих игр.
A39: see | B39: Что посмотреть | C39: Отражение пика Ленина (7134 м) в озере; стена Заалайского хребта; базовый лагерь Ачык-Таш рядом; трек на «Перевал путешественников» (~4100 м) и к леднику Ленина; сурки на лугах (too.kg, Visit Alay, TripAdvisor).
A40: skip | B40: Кому не стоит | C40: Ты не успеваешь оформить пограничный пропуск (10–20 дней). Плохо переносишь высоту — ночёвка на ~3500 м без акклиматизации тяжела. Тебе хватит вида на пик Ленина с трассы у Сары-Таша.
A42: #section | B42: Медиа
A43: #table:photos | B43: Фото — 2
...

Sheet kg-0007
A1: #title | B1: Ущелье Чычкан | C1: kg-0007 · ← к оглавлению
A2: #section | B2: Основное
A3: id | B3: ID места (kg-…, alt-…) | C3: kg-0007
A4: country | B4: Страна (kg / alt) | C4: kg
A5: publish | B5: Публикация | C5: опубликовано
A6: status | B6: Статус проверки | C6: Проверено
A7: name | B7: Название | C7: Ущелье Чычкан
A8: full | B8: Полное название | C8: Ущелье Чычкан
A9: cat | B9: Категория | C9: Ущелье
A10: reg | B10: Регион | C10: Джалал-Абадская область
A11: dist | B11: Район | C11: Токтогульский район
A12: lat | B12: Широта | C12: 42.1278
A13: lon | B13: Долгота | C13: 72.7858
A14: elev | B14: Высота | C14: Средняя высота ущелья около 2200 м; небольшие озёра на склонах — около 3000 м (too.kg). Скалы поднимаются примерно на 1000 м над рекой (central-asia.live).
A15: near | B15: Ближайший пункт | C15: Внутри ущелья сёл нет — только придорожные кафе, форелевые хозяйства и турбаза. Ближайший город — Токтогул (у выхода ущелья к водохранилищу, ~30–50 км по трассе — не уточнено); по OSM в ~23 км по прямой от точки каталога — Мазар-Суу.
A16: tags | B16: Теги (через ;) | C16: gorges;any-car;easy;free;no-car;hiking;horses
A17: top | B17: В топе (да/нет) | C17: нет
A18: rank | B18: Место в рейтинге | C18: 64
A19: updated_at | B19: Изменено (дата)
A20: updated_by | B20: Кто изменил
A22: #section | B22: Коротко на карточке (плашки)
A23: months | B23: Месяцы сезона (1;2;…12) | C23: 5;6;7;8;9;10
A24: month_scores | B24: Оценка месяцев (JSON: месяц → 2 лучшее, 1 подходит), напр. {"6":1,"7":2}
A25: s_diff | B25: Сложность (коротко) | C25: Лёгкая
A26: s_when | B26: Когда (коротко) | C26: Май – окт
A27: s_acc | B27: Доступ (коротко) | C27: На любой машине
A28: s_onsite | B28: Время на месте (коротко) | C28: от 1–2 ч до дня
A29: s_entry | B29: Вход (коротко) | C29: Бесплатно
A30: s_net | B30: Связь (коротко) | C30: Мобильной связи в…
A31: rating_v | B31: Рейтинг | C31: 4.8
A32: rating_n | B32: Кол-во оценок | C32: 36
A33: rating_src | B33: Источник рейтинга | C33: Google
A35: #section | B35: Обзор — тексты
A36: short | B36: Коротко (1–2 предложения) | C36: Чычкан — около 30 км живописного лесистого ущелья одноимённой реки на трассе Бишкек — Ош между перевалом Ала-Бель и Токтогульским водохранилищем: ели, луга, мёд, форелевые хозяйства и придорожные кафе.
A37: desc | B37: Описание | C37: Ущелье Чычкан тянется примерно на 30 км вдоль реки Чычкан в северной части Ферганского хребта (central-asia.live) — от перевала Ала-Бель на юг к Токтогульскому водохранилищу, куда впадает бурная река (too.kg). Средняя высота — около 2200 м; склоны покрыты тянь-шанской елью, цветами и ягодниками, выше — небольшие озёра на ~3000 м. Название переводится как «мышь» — из-за множества полевых мышей в норах на склонах (too.kg). Ущелье известно ароматным мёдом и лекарственными травами; вдоль трассы работают кафе, форелевые хозяйства, гостевые дома и турбаза «Чычкан» (~240 км трассы Бишкек — Ош). Часть территории — государственный заказник «Чычкан». Мобильной связи в ущелье почти нет (too.kg).
A38: guide | B38: Почему стоит приехать / текст аудиогида | C38: Чычкан — лучшая остановка на долгом пути Бишкек — Ош: после голых склонов Суусамыра и Ала-Беля дорога ныряет в еловый лес вдоль бурной реки. Остановись пообедать форелью в одном из придорожных хозяйств и купи местный мёд — ущелье им славится. Если есть пара часов, поднимись по боковым долинам — на высоте около 3000 м прячутся небольшие озёра. Воду из реки не пей — бери из родников или в кафе. Связи нет, так что предупреди близких, что пропадёшь на пару часов.
A39: see | B39: Что посмотреть | C39: Река Чычкан и еловые склоны вдоль трассы; боковые долины (например, река Итагар) и высокогорные озёра (~3000 м); пасеки и продажа мёда; форелевые хозяйства; водопады, пещеры и петроглифы в окрестностях (central-asia.live — без конкретных мест); перевал Ала-Бель на севере и Токтогульское водохранилище на юге.
A40: skip | B40: Кому не стоит | C40: Ты летишь Бишкек — Ош самолётом и не едешь по трассе — специально сюда ехать 5–6 часов нет смысла. Ищешь уединённые места — у трассы плотное движение. Нужна связь — её здесь почти нет.
A42: #section | B42: Медиа
A43: #table:photos | B43: Фото — 2
...

Sheet kg-0009
A1: #title | B1: Озеро Сары-Челек | C1: kg-0009 · ← к оглавлению
A2: #section | B2: Основное
A3: id | B3: ID места (kg-…, alt-…) | C3: kg-0009
A4: country | B4: Страна (kg / alt) | C4: kg
A5: publish | B5: Публикация | C5: опубликовано
A6: status | B6: Статус проверки | C6: Проверено
A7: name | B7: Название | C7: Озеро Сары-Челек
A8: full | B8: Полное название | C8: Озеро Сары-Челек
A9: cat | B9: Категория | C9: Озеро
A10: reg | B10: Регион | C10: Джалал-Абадская область
A11: dist | B11: Район | C11: Аксыйский район
A12: lat | B12: Широта | C12: 41.8899
A13: lon | B13: Долгота | C13: 71.9602
A14: elev | B14: Высота | C14: 1878 м — уровень озера (Trip to Kyrgyzstan, central-asia.guide). Хвойные леса начинаются с ~2100 м (govori.tv).
A15: near | B15: Ближайший пункт | C15: Аркыт — село у подножия заповедника (~200 семей), база размещения; до берега основного озера ~15 км по дороге заповедника (central-asia.guide, journalofnomads, govori.tv).
A16: tags | B16: Теги (через ;) | C16: lakes;any-car;easy;top;no-car;hiking;horses;yurts
A17: top | B17: В топе (да/нет) | C17: да
A18: rank | B18: Место в рейтинге | C18: 7
A19: updated_at | B19: Изменено (дата)
A20: updated_by | B20: Кто изменил
A22: #section | B22: Коротко на карточке (плашки)
A23: months | B23: Месяцы сезона (1;2;…12) | C23: 5;6;7;8;9;10
A24: month_scores | B24: Оценка месяцев (JSON: месяц → 2 лучшее, 1 подходит), напр. {"6":1,"7":2}
A25: s_diff | B25: Сложность (коротко) | C25: Лёгкая
A26: s_when | B26: Когда (коротко) | C26: Май – окт
A27: s_acc | B27: Доступ (коротко) | C27: На любой машине
A28: s_onsite | B28: Время на месте (коротко) | C28: ≈4 ч
A29: s_entry | B29: Вход (коротко) | C29: Источники расходятся
A30: s_net | B30: Связь (коротко) | C30: По наблюдениям hiking
A31: rating_v | B31: Рейтинг | C31: 4.7
A32: rating_n | B32: Кол-во оценок | C32: 476
A33: rating_src | B33: Источник рейтинга | C33: Google
A35: #section | B35: Обзор — тексты
A36: short | B36: Коротко (1–2 предложения) | C36: Сары-Челек — бирюзовое горное озеро на высоте 1878 м и глубиной до 234 м в Сары-Челекском биосферном заповеднике ЮНЕСКО в Чаткальском хребте, окружённое еловыми и ореховыми лесами; всего в заповеднике семь озёр.
A37: desc | B37: Описание | C37: Сары-Челек — крупнейшее озеро одноимённого государственного биосферного заповедника (входит во Всемирную сеть биосферных резерватов ЮНЕСКО) в Чаткальском хребте Западного Тянь-Шаня. Длина озера около 6,2 км, ширина до 2,6 км, глубина до 234 м, уровень — 1878 м (central-asia.guide). Площадь заповедника — 23 868 га; в нём семь озёр: Сары-Челек, Кыла-Кёль, Чойчок-Кёль, Бакалы-Кёль, Арам-Кёль, Ийри-Кёль и Туюк-Кёль (govori.tv). Берега покрыты еловыми, пихтовыми, ореховыми и яблоневыми лесами. Въезд — от села Аркыт через КПП заповедника, дальше ~15 км по серпантину до парковки у основного озера; у берега есть туалет, урны, крытые беседки и зоны для палаток (central-asia.guide). Отсюда проложена тропа к системе малых озёр и панораме (7,1 км, ~3 ч 15 мин, набор 760 м — hiking.kg). В 2026 году запланирована установка автоматизированного КПП (time.kg, 08.06.2026).
A38: guide | B38: Почему стоит приехать / текст аудиогида | C38: Сары-Челек — главная жемчужина запада Кыргызстана: бирюзовая вода глубиной до 234 м в рамке из елей и орешников. Ночуй в Аркыте и выезжай к озеру рано утром, пока гладь зеркальная и туристов мало. Не ограничивайся парковкой: тропа к малым озёрам и на панораму (около 7 км и 3 часа) открывает вид на цепочку озёр сверху. Купаться, разводить костры и рвать растения в заповеднике нельзя — это строгая ООПТ. Бери наличные сомы: плату берут на шлагбауме, а тарифы на месте могут отличаться от того, что пишут в блогах.
A39: see | B39: Что посмотреть | C39: Основное озеро Сары-Челек (бирюзовая вода, 234 м глубины); цепочка малых озёр (Ийри-Кёль, Кыла-Кёль, Чойчок-Кёль, Бакалы-Кёль, Арам-Кёль, Туюк-Кёль); панорама над озёрами (тропа 7,1 км); еловые и ореховые леса; дикие яблони (govori.tv, hiking.kg).
A40: skip | B40: Кому не стоит | C40: У тебя меньше 3–4 дней на запад страны: из Бишкека ~540 км и ~11 ч в одну сторону (hiking.kg). Ты хочешь купаться и жарить шашлык у воды — в заповеднике это запрещено. Едешь до середины мая — дорога может быть закрыта снегом.
A42: #section | B42: Медиа
A43: #table:photos | B43: Фото — 2
...

Sheet kg-0010
A1: #title | B1: Наскальная галерея Чолпон-Аты | C1: kg-0010 · ← к оглавлению
A2: #section | B2: Основное
A3: id | B3: ID места (kg-…, alt-…) | C3: kg-0010
A4: country | B4: Страна (kg / alt) | C4: kg
A5: publish | B5: Публикация | C5: опубликовано
A6: status | B6: Статус проверки | C6: Проверено
A7: name | B7: Название | C7: Наскальная галерея Чолпон-Аты
A8: full | B8: Полное название | C8: Наскальная галерея Чолпон-Аты (Музей петроглифов под открытым небом)
A9: cat | B9: Категория | C9: Петроглифы
A10: reg | B10: Регион | C10: Иссык-Кульская область
A11: dist | B11: Район | C11: Иссык-Кульский район
A12: lat | B12: Широта | C12: 42.6579
A13: lon | B13: Долгота | C13: 77.0568
A14: elev | B14: Высота | C14: ≈1700–1750 м (расчёт: Чолпон-Ата у озера ≈1620 м, поле петроглифов на пологом предгорном склоне выше города; точная отметка входа источниками не публикуется)
A15: near | B15: Ближайший пункт | C15: Чолпон-Ата: ≈3 км от центра города, в предгорьях над аэродромом (взлётной полосой); до часа пешком от центра.
A16: tags | B16: Теги (через ;) | C16: culture;any-car;easy;no-car;hiking
A17: top | B17: В топе (да/нет) | C17: нет
A18: rank | B18: Место в рейтинге | C18: 37
A19: updated_at | B19: Изменено (дата)
A20: updated_by | B20: Кто изменил
A22: #section | B22: Коротко на карточке (плашки)
A23: months | B23: Месяцы сезона (1;2;…12) | C23: 4;5;6;7;8;9;10
A24: month_scores | B24: Оценка месяцев (JSON: месяц → 2 лучшее, 1 подходит), напр. {"6":1,"7":2}
A25: s_diff | B25: Сложность (коротко) | C25: Лёгкая
A26: s_when | B26: Когда (коротко) | C26: Апр – окт
A27: s_acc | B27: Доступ (коротко) | C27: На любой машине
A28: s_onsite | B28: Время на месте (коротко) | C28: 30–40 мин
A29: s_entry | B29: Вход (коротко) | C29: По отзывам Яндекс Карт
A30: s_net | B30: Связь (коротко) | C30: Чолпон-Ата
A31: rating_v | B31: Рейтинг | C31: 4.2
A32: rating_n | B32: Кол-во оценок | C32: 886
A33: rating_src | B33: Источник рейтинга | C33: Google
A35: #section | B35: Обзор — тексты
A36: short | B36: Коротко (1–2 предложения) | C36: Поле валунов площадью ≈42 га на склоне над Чолпон-Атой с сотнями петроглифов бронзового века — средневековья (II тыс. до н. э. — IV в. н. э. и позже): козлы, олени, барсы, сцены охоты. Три размеченных маршрута от 800 м до 3 км.
A37: desc | B37: Описание | C37: Музей петроглифов под открытым небом занимает около 42 гектаров каменистого предгорья между хребтом Кюнгей-Ала-Тоо и озером. На тысячах валунов, принесённых ледником, выбиты изображения горных козлов (их большинство: в одной выборке из 409 петроглифов — 285 козлов), оленей, верблюдов, снежных барсов, сцены охоты, битв и праздников. Самые древние относятся к I–II тысячелетию до н. э. (сако-усуньское время), часть — к тюркской эпохе и средневековью; единой даты у памятника нет. Кроме рисунков на территории — каменные круги, курганы, балбалы и остатки стен. Проложены три маршрута: 800 м (30–40 мин, с синими указателями — самый обустроенный), 1,5 км (≈1,5 ч) и 3 км (≈2 ч); у входа — главный камень с наиболее эффектными рисунками. Таблички на трёх языках, но их мало; часть петроглифов приходится искать самому. Тени и воды на территории нет; по полю ходит скот. Готовилась номинация в список ЮНЕСКО, объект в список не включён. С верхней части поля открывается панорама Иссык-Куля и Терскей-Ала-Тоо.
A38: guide | B38: Почему стоит приехать / текст аудиогида | C38: Начни с большого камня у кассы — на нём самые чёткие барсы и козлы, а потом иди по синим флажкам короткого круга: за 40 минут увидишь главное, остальное поле — для тех, кто любит искать рисунки как сокровища. Смотри на валуны с южной, прокалённой солнцем стороны: древние мастера выбирали тёмный «пустынный загар», на котором светлые линии видны лучше всего, поэтому рисунки часто смотрят на озеро. Приходи утром или к вечеру — косой свет вытягивает тени из выбитых линий, а в полдень петроглифы «исчезают». Смотрителю можно заплатить за экскурсию: без рассказа поле выглядит как россыпь камней, с ним — как галерея. Не вставай на камни с рисунками и не обводь их — они не защищены ничем, кроме твоей аккуратности.
A39: see | B39: Что посмотреть | C39: Главный камень у входа с барсами и козлами; петроглифы со сценами охоты, оленями, верблюдами; каменные круги и курганы, балбалы; панорама Иссык-Куля с верхней части поля; маршруты 800 м / 1,5 км / 3 км.
A40: skip | B40: Кому не стоит | C40: Если ждёшь музей с витринами и кондиционером — это голое поле камней без тени. Если ты уже видел Саймалуу-Таш или Чолпон-Ата — не главный интерес: рисунков немного относительно площади, и без гида многие их не находят. Если жара выше 30° и нет шляпы — лучше отложить до вечера.
A42: #section | B42: Медиа
A43: #table:photos | B43: Фото — 2
...

Sheet kg-0011
A1: #title | B1: Гумбез Манаса | C1: kg-0011 · ← к оглавлению
A2: #section | B2: Основное
A3: id | B3: ID места (kg-…, alt-…) | C3: kg-0011
A4: country | B4: Страна (kg / alt) | C4: kg
A5: publish | B5: Публикация | C5: опубликовано
A6: status | B6: Статус проверки | C6: Проверено
A7: name | B7: Название | C7: Гумбез Манаса
A8: full | B8: Полное название | C8: Гумбез Манаса (мавзолей в историко-культурном комплексе «Манас Ордо»)
A9: cat | B9: Категория | C9: Мавзолей
A10: reg | B10: Регион | C10: Таласская область
A11: dist | B11: Район | C11: Таласский район
A12: lat | B12: Широта | C12: 42.525007
A13: lon | B13: Долгота | C13: 72.382201
A14: elev | B14: Высота | C14: Около 1357 м (Nomad's Land).
